Workbook

Sheet Cancel Stop Hgl-Odz-Hgl
A1: ICE Delay Odzg | C1: 0.0020833333 | D1: 0.0027777778 | E1: 0.0034722222 | F1: 0.0041666667 | G1: 0.0048611111 | H1: 0.0055555556 | I1: 0.00625 | J1: 0.0069444444 | K1: 0.0076388889 | L1: 0.0083333333 | M1: 0.0090277778 | N1: 0.0097222222 | O1: 0.010416667 | P1: 0.013888889 | Q1: 0.017361111 | R1: Originele vertrektijd Odzg = 09:56:06 | U1: Originele vertrektijd Odzg = 09:56:06
A2: 140/240 | B2: Amersfoort | C2: 0 | D2: 0 | E2: 0 | F2: 0.00016203704 | G2: 0.00085648148 | H2: 0.0019675926 | I2: 0.0022453704 | J2: 0.0096990741 | K2: 0.0096990741 | L2: 0.0096990741 | M2: 0.0096990741 | N2: 0.0096990741 | O2: 0.0096990741 | P2: 0.017592593 | Q2: 0.017592593 | R2: A140-late | U2: Vertraging in Amersfoort
A3: 1700 | B3: Utrecht | C3: 0.0018518519 | D3: 0.0018518519 | E3: 0.0022685185 | F3: 0.002962963 | G3: 0.011365741 | H3: 0.011365741 | I3: 0.011365741 | J3: 0.0036805556 | K3: 0.0036805556 | L3: 0.0061111111 | M3: 0.0061111111 | N3: 0.0061111111 | O3: 0.0061111111 | P3: 0.0015509259 | Q3: 0.0015509259 | R3: C1700-17 | U3: Vertraging van nationale treinen (eerste hub buiten corridor)
A4: 7000 | B4: Apeldoorn | C4: 0.0016666667 | D4: 0.0016666667 | E4: 0.0020833333 | F4: 0.0027777778 | G4: 0.0034722222 | H4: 0.0041666667 | I4: 0.0048611111 | J4: 0 | K4: 0 | L4: 0 | M4: 0 | N4: 0 | O4: 0 | P4: 0.0013657407 | Q4: 0.0013657407 | R4: A7000-15
A5: 31200 | B5: Goor | C5: 0.0016203704 | D5: 0.0016203704 | E5: 0.0016203704 | F5: 0.0016203704 | G5: 0.0016203704 | H5: 0.0016203704 | I5: 0.0016203704 | J5: 0.0016203704 | K5: 0.0016203704 | L5: 0.0016203704 | M5: 0.0016203704 | N5: 0.0016203704 | O5: 0.0016203704 | P5: 0.0016203704 | Q5: 0.0016203704 | R5: D31200-18
A6: 7900 | B6: Nijverdal | C6: 0 | D6: 0 | E6: 0.00034722222 | F6: 0.0010416667 | G6: 0.0017361111 | H6: 0.0024305556 | I6: 0.003125 | J6: 0.0046296296 | K6: 0.0046296296 | L6: 0.00083333333 | M6: 0.0021064815 | N6: 0.0028009259 | O6: 0.0034953704 | P6: 0 | Q6: 0 | R6: A7900-17
A7: 31300 | B7: Amersfoort | C7: 0 | D7: 0 | E7: 0 | F7: 0 | G7: 0 | H7: 0.00092592593 | I7: 0.0012037037 | J7: 0 | K7: 0 | L7: 0 | M7: 0 | N7: 0 | O7: 0 | P7: 0 | Q7: 0 | R7: A31300-19
A8: 3600 | B8: Zwolle | C8: 0.0042592593 | D8: 0.0042592593 | E8: 0.0046759259 | F8: 0.0053703704 | G8: 0.0060648148 | H8: 0.00094907407 | I8: 0.00094907407 | J8: 0.00094907407 | K8: 0.00094907407 | L8: 0.00094907407 | M8: 0.00094907407 | N8: 0.00094907407 | O8: 0.00094907407 | P8: 0.00094907407 | Q8: 0.00094907407 | R8: A3600-5
A9: 20350 | B9: Hengelo | C9: 0 | D9: 0 | E9: 0 | F9: 0 | G9: 0 | H9: 0 | I9: 0 | J9: 0 | K9: 0 | L9: 0 | M9: 0 | N9: 0 | O9: 0.00069444444 | P9: 0 | Q9: 0 | R9: B36100-18 | S9: Wordt niet meegenomen in punctualiteit
A10: 31200 | B10: Hengelo | C10: - | D10: - | E10: - | F10: - | G10: - | H10: - | I10: - | J10: - | K10: - | L10: - | M10: - | N10: - | O10: - | P10: - | Q10: - | R10: Komt niet vanaf Odz dus geen aankomstvertr. | U10: Vetragingen bij transfer hubs
A11: 31200 | B11: Zutphen | C11: 0.000625 | D11: 0.000625 | E11: 0.000625 | F11: 0.000625 | G11: 0.000625 | H11: 0.000625 | I11: 0.000625 | J11: 0.000625 | K11: 0.000625 | L11: 0.000625 | M11: 0.000625 | N11: 0.000625 | O11: 0.000625 | P11: 0.000625 | Q11: 0.000625
A12: 7900 | B12: Zwolle | C12: 0 | D12: 0 | E12: 0 | F12: 0 | G12: 0 | H12: 0 | I12: 0 | J12: 0.00081018519 | K12: 0.00081018519 | L12: 0 | M12: 0 | N12: 0 | O12: 0 | P12: 0 | Q12: 0
A13: Total delay all trains in the scope at the first hub outside the corridor | C13: =SUM(C3:C8) -> 0.0093981481 | D13: =SUM(D3:D8) -> 0.0093981481 | E13: =SUM(E3:E8) -> 0.01099537 | F13: =SUM(F3:F8) -> 0.013773148 | G13: =SUM(G3:G8) -> 0.024259259 | H13: =SUM(H3:H8) -> 0.021458333 | I13: =SUM(I3:I8) -> 0.023125 | J13: =SUM(J3:J8) -> 0.01087963 | ... Q13: =SUM(Q3:Q8) -> 0.0054861111 | U13: Totale vertraging (ICE en nationale treinen)
A15: 140/240 | B15: Amersfoort | C15: =C2<6/1440 -> TRUE | D15: =D2<6/1440 -> TRUE | E15: =E2<6/1440 -> TRUE | F15: =F2<6/1440 -> TRUE | G15: =G2<6/1440 -> TRUE | H15: =H2<6/1440 -> TRUE | I15: =I2<6/1440 -> TRUE | J15: =J2<6/1440 -> FALSE | ... Q15: =Q2<6/1440 -> FALSE | U15: Is de ICE op tijd?
A16: 1700 | B16: Utrecht | C16: =C3<3/1440 -> TRUE | D16: =D3<3/1440 -> TRUE | E16: =E3<3/1440 -> FALSE | F16: =F3<3/1440 -> FALSE | G16: =G3<3/1440 -> FALSE | H16: =H3<3/1440 -> FALSE | I16: =I3<3/1440 -> FALSE | J16: =J3<3/1440 -> FALSE | ... Q16: =Q3<3/1440 -> TRUE | U16: Zijn de nationale treinen op tijd? | Y16: Met hoe veel minuten vetraging haalt de ICE zn slot in Amersfoort?
A17: 7000 | B17: Apeldoorn | C17: =C4<3/1440 -> TRUE | D17: =D4<3/1440 -> TRUE | E17: =E4<3/1440 -> FALSE | F17: =F4<3/1440 -> FALSE | G17: =G4<3/1440 -> FALSE | H17: =H4<3/1440 -> FALSE | I17: =I4<3/1440 -> FALSE | J17: =J4<3/1440 -> TRUE | ... Q17: =Q4<3/1440 -> TRUE | Y17: Hoe veel minuten te laat mag de 31200 en 7900 komen om hun domestic transfer te halen?
A18: 31200 | B18: Goor | C18: =C5<3/1440 -> TRUE | D18: =D5<3/1440 -> TRUE | E18: =E5<3/1440 -> TRUE | F18: =F5<3/1440 -> TRUE | G18: =G5<3/1440 -> TRUE | H18: =H5<3/1440 -> TRUE | I18: =I5<3/1440 -> TRUE | J18: =J5<3/1440 -> TRUE | ... Q18: =Q5<3/1440 -> TRUE
A19: 7900 | B19: Nijverdal | C19: =C6<3/1440 -> TRUE | D19: =D6<3/1440 -> TRUE | E19: =E6<3/1440 -> TRUE | F19: =F6<3/1440 -> TRUE | G19: =G6<3/1440 -> TRUE | H19: =H6<3/1440 -> FALSE | I19: =I6<3/1440 -> FALSE | J19: =J6<3/1440 -> FALSE | ... Q19: =Q6<3/1440 -> TRUE
A20: 31300 | B20: Amersfoort | C20: =C7<3/1440 -> TRUE | D20: =D7<3/1440 -> TRUE | E20: =E7<3/1440 -> TRUE | F20: =F7<3/1440 -> TRUE | G20: =G7<3/1440 -> TRUE | H20: =H7<3/1440 -> TRUE | I20: =I7<3/1440 -> TRUE | J20: =J7<3/1440 -> TRUE | ... Q20: =Q7<3/1440 -> TRUE
A21: 3600 | B21: Zwolle | C21: =C8<3/1440 -> FALSE | D21: =D8<3/1440 -> FALSE | E21: =E8<3/1440 -> FALSE | F21: =F8<3/1440 -> FALSE | G21: =G8<3/1440 -> FALSE | H21: =H8<3/1440 -> TRUE | I21: =I8<3/1440 -> TRUE | J21: =J8<3/1440 -> TRUE | ... Q21: =Q8<3/1440 -> TRUE
A22: 20350 | B22: Hengelo | C22: =C9<3/1440 -> TRUE | D22: =D9<3/1440 -> TRUE | E22: =E9<3/1440 -> TRUE | F22: =F9<3/1440 -> TRUE | G22: =G9<3/1440 -> TRUE | H22: =H9<3/1440 -> TRUE | I22: =I9<3/1440 -> TRUE | J22: =J9<3/1440 -> TRUE | ... Q22: =Q9<3/1440 -> TRUE
A23: 31200 | B23: Hengelo | C23: 1 | D23: 1 | E23: 1 | F23: 1 | G23: 1 | H23: 1 | I23: 1 | J23: 1 | K23: 1 | L23: 1 | M23: 1 | N23: 1 | O23: 1 | P23: 1 | Q23: 1
A24: 31200 | B24: Zutphen | C24: =C11<3/1440 -> TRUE | D24: =D11<3/1440 -> TRUE | E24: =E11<3/1440 -> TRUE | F24: =F11<3/1440 -> TRUE | G24: =G11<3/1440 -> TRUE | H24: =H11<3/1440 -> TRUE | I24: =I11<3/1440 -> TRUE | J24: =J11<3/1440 -> TRUE | ... Q24: =Q11<3/1440 -> TRUE
A25: 7900 | B25: Zwolle | C25: =C12<3/1440 -> TRUE | D25: =D12<3/1440 -> TRUE | E25: =E12<3/1440 -> TRUE | F25: =F12<3/1440 -> TRUE | G25: =G12<3/1440 -> TRUE | H25: =H12<3/1440 -> TRUE | I25: =I12<3/1440 -> TRUE | J25: =J12<3/1440 -> TRUE | ... Q25: =Q12<3/1440 -> TRUE
A26: Punctuality | C26: =COUNTIF(C16:C21,TRUE) / 6 -> 0.83333333 | D26: =COUNTIF(D16:D21,TRUE) / 6 -> 0.83333333 | E26: =COUNTIF(E16:E21,TRUE) / 6 -> 0.5 | F26: =COUNTIF(F16:F21,TRUE) / 6 -> 0.5 | G26: =COUNTIF(G16:G21,TRUE) / 6 -> 0.5 | H26: =COUNTIF(H16:H21,TRUE) / 6 -> 0.5 | I26: =COUNTIF(I16:I21,TRUE) / 6 -> 0.5 | J26: =COUNTIF(J16:J21,TRUE) / 6 -> 0.66666667 | ... Q26: =COUNTIF(Q16:Q21,TRUE) / 6 -> 1 | U26: Punctualiteit nationale treinen
A28: Diff ICE delay BB and Amf | C28: =C2-C1 -> -0.0020833333 | D28: =D2-D1 -> -0.0027777778 | E28: =E2-E1 -> -0.0034722222 | F28: =F2-F1 -> -0.0040046296 | G28: =G2-G1 -> -0.0040046296 | H28: =H2-H1 -> -0.003587963 | I28: =I2-I1 -> -0.0040046296 | J28: =J2-J1 -> 0.0027546296 | ... Q28: =Q2-Q1 -> 0.00023148148 | R28: + -> Extra delay
R29: - -> less delay
A30: Als/Hoeveel de ICE te vroeg is in Amf | C30: -00:01:54 | D30: -00:01:54 | E30: -00:01:54
A31: Regional transfer | C31: =(C20+C21+C23+C24+C25)/5 -> 0.8 | D31: =(D20+D21+D23+D24+D25)/5 -> 0.8 | E31: =(E20+E21+E23+E24+E25)/5 -> 0.8 | F31: =(F20+F21+F23+F24+F25)/5 -> 0.8 | G31: =(G20+G21+G23+G24+G25)/5 -> 0.8 | H31: =(H20+H21+H23+H24+H25)/5 -> 1 | I31: =(I20+I21+I23+I24+I25)/5 -> 1 | J31: =(J20+J21+J23+J24+J25)/5 -> 1 | ... Q31: =(Q20+Q21+Q23+Q24+Q25)/5 -> 1 | U31: Gemiste transfers
M33: Hengelo | N33: Oldenzaal
A34: Wat is er gedaan in OpenTrack om dit te bereiken? | L34: C31200-13 | M34: 0.40763889 | N34: 0.41458333
A35: Nieuwe itinerary gemaakt Zp-Hgl | L35: D31200-18 | N35: 0.41875 | O35: 0.42569444
A36: Nieuwe itinerary gemaakt Hgl-Zp | L36: A31200-15 | M36: 0.42847222 | N36: 0.43541667
A37: D31200-18: Itinerary veranderd | L37: B31200-20 | N37: 0.43958333 | O37: 0.44652778
A38: A31200-15: Itinerary veranderd
A39: D31200-18: Connectie met C31200-13 in Oldenzaal is verbroken
A40: D31200-18: Connectie met A31200-15 in Hengelo is toegevoegd
A41: C31200-13: Connectie met B31200-20 ipv D31200-18 zodat deze een half uur later gaat
A42: B31200-20: Connectie met C31200-13 ipv A31200-15
A43: A31200-15: Connectie met D31200-18 in Hengelo toegevoegd
...

Sheet ICE Waits
A1: ICE Delay Odzg | C1: 0.0020833333 | D1: 0.0027777778 | E1: 0.0034722222 | F1: 0.0041666667 | G1: 0.0048611111 | H1: 0.0055555556 | I1: 0.00625 | J1: 0.0069444444 | K1: 0.0076388889 | L1: 0.0083333333 | M1: 0.0090277778 | N1: 0.0097222222 | O1: 0.010416667 | P1: 0.013888889 | Q1: 0.017361111 | R1: Originele vertrektijd Odzg = 09:56:06
A2: 140/240 | B2: Amersfoort | C2: 0 | D2: 0 | E2: 0.00048611111 | F2: 0.0096990741 | G2: 0.0096990741 | H2: 0.0096990741 | I2: 0.0096990741 | J2: 0.0096990741 | K2: 0.0096990741 | L2: 0.0096990741 | M2: 0.0096990741 | N2: 0.0096990741 | O2: 0.009537037 | P2: 0.017592593 | Q2: 0.017592593 | R2: A140-late | T2: Originele aankomst Amf = 10:24:00
A3: 1700 | B3: Utrecht | C3: 0.0019212963 | D3: 0.0026157407 | E3: 0.003287037 | F3: 0.0061111111 | G3: 0.0061111111 | H3: 0.0061111111 | I3: 0.0037268519 | J3: 0.0061111111 | K3: 0.0061111111 | L3: 0.0061111111 | M3: 0.0061111111 | N3: 0.0061111111 | O3: 0.011365741 | P3: 0.0015509259 | Q3: 0.0015509259 | R3: C1700-17
A4: 7000 | B4: Apeldoorn | C4: 0.0017361111 | D4: 0.0024074074 | E4: 0.0031018519 | F4: 0 | G4: 0 | H4: 0 | I4: 0 | J4: 0 | K4: 0 | L4: 0 | M4: 0 | N4: 0 | O4: 0 | P4: 0.0013657407 | Q4: 0.0013657407 | R4: A7000-15
A5: 31200 | B5: Goor | C5: 0.0028703704 | D5: 0.0028703704 | E5: 0.0029398148 | F5: 0 | G5: 0 | H5: 0 | I5: 0 | J5: 0 | K5: 0 | L5: 0 | M5: 0 | N5: 0 | O5: 0 | P5: 0 | Q5: 0 | R5: D31200-18
A6: 7900 | B6: Nijverdal | C6: 0.00074074074 | D6: 0.0013657407 | E6: 0.0020601852 | F6: 0.0016203704 | G6: 0.0016203704 | H6: 0.0016203704 | I6: 0.0016203704 | J6: 0.0015972222 | K6: 0.0016203704 | L6: 0.0024305556 | M6: 0.003125 | N6: 0.0038194444 | O6: 0 | P6: 0 | Q6: 0 | R6: A7900-17
A7: 31300 | B7: Amersfoort | C7: 0 | D7: 0 | E7: 0 | F7: 0 | G7: 0 | H7: 0 | I7: 0 | J7: 0 | K7: 0 | L7: 0 | M7: 0 | N7: 0 | O7: 0 | P7: 0 | Q7: 0 | R7: A31300-19
A8: 3600 | B8: Zwolle | C8: 0.0043518519 | D8: 0.005 | E8: 0.0056944444 | F8: 0.00094907407 | G8: 0.00094907407 | H8: 0.00094907407 | I8: 0.00094907407 | J8: 0.00094907407 | K8: 0.00094907407 | L8: 0.00094907407 | M8: 0.00094907407 | N8: 0.00094907407 | O8: 0.00094907407 | P8: 0.00094907407 | Q8: 0.00094907407 | R8: A3600-5
A9: 20350 | B9: Hengelo | C9: 0 | D9: 0 | E9: 0 | F9: 0 | G9: 0 | H9: 0 | I9: 0 | J9: 0 | K9: 0 | L9: 0 | M9: 0 | N9: 2.3148148e-05 | O9: 0.00074074074 | P9: 0.0040972222 | Q9: 0 | R9: B36100-18
A10: 31200 | B10: Hengelo | C10: 0.0032638889 | D10: 0.0038888889 | E10: 0.0045833333 | F10: 0.00011574074 | G10: 0.00011574074 | H10: 0.00011574074 | I10: 0.00011574074 | J10: 0.00011574074 | K10: 0.00011574074 | L10: 0.00011574074 | M10: 0.00011574074 | N10: 0.00011574074 | O10: 0.00011574074 | P10: 0.00011574074 | Q10: 0.00011574074
A11: 31200 | B11: Zutphen | C11: 0.001875 | D11: 0.001875 | E11: 0.0019444444 | F11: 0.00016203704 | G11: 0.00016203704 | H11: 0.00016203704 | I11: 0.00016203704 | J11: 0.00016203704 | K11: 0.00016203704 | L11: 0.00016203704 | M11: 0.00016203704 | N11: 0.00016203704 | O11: 0.00016203704 | P11: 0.00016203704 | Q11: 0.00016203704
A12: 7900 | B12: Zwolle | C12: 0 | D12: 0 | E12: 0 | F12: 0 | G12: 0 | H12: 0 | I12: 0 | J12: 0 | K12: 0 | L12: 0 | M12: 0 | N12: 0 | O12: 0 | P12: 0 | Q12: 0
A13: Total delay all trains in the scope at the first hub outside the corridor | C13: =SUM(C3:C8) -> 0.01162037 | D13: =SUM(D3:D8) -> 0.014259259 | E13: =SUM(E3:E8) -> 0.017083333 | F13: =SUM(F3:F8) -> 0.0086805556 | G13: =SUM(G3:G8) -> 0.0086805556 | H13: =SUM(H3:H8) -> 0.0086805556 | I13: =SUM(I3:I8) -> 0.0062962963 | J13: =SUM(J3:J8) -> 0.0086574074 | ... Q13: =SUM(Q3:Q8) -> 0.0038657407
A15: 140/240 | B15: Amersfoort | C15: =C2<6/1440 -> TRUE | D15: =D2<6/1440 -> TRUE | E15: =E2<6/1440 -> TRUE | F15: =F2<6/1440 -> FALSE | G15: =G2<6/1440 -> FALSE | H15: =H2<6/1440 -> FALSE | I15: =I2<6/1440 -> FALSE | J15: =J2<6/1440 -> FALSE | ... Q15: =Q2<6/1440 -> FALSE
A16: 1700 | B16: Utrecht | C16: =C3<3/1440 -> TRUE | D16: =D3<3/1440 -> FALSE | E16: =E3<3/1440 -> FALSE | F16: =F3<3/1440 -> FALSE | G16: =G3<3/1440 -> FALSE | H16: =H3<3/1440 -> FALSE | I16: =I3<3/1440 -> FALSE | J16: =J3<3/1440 -> FALSE | ... Q16: =Q3<3/1440 -> TRUE
A17: 7000 | B17: Apeldoorn | C17: =C4<3/1440 -> TRUE | D17: =D4<3/1440 -> FALSE | E17: =E4<3/1440 -> FALSE | F17: =F4<3/1440 -> TRUE | G17: =G4<3/1440 -> TRUE | H17: =H4<3/1440 -> TRUE | I17: =I4<3/1440 -> TRUE | J17: =J4<3/1440 -> TRUE | ... Q17: =Q4<3/1440 -> TRUE
A18: 31200 | B18: Goor | C18: =C5<3/1440 -> FALSE | D18: =D5<3/1440 -> FALSE | E18: =E5<3/1440 -> FALSE | F18: =F5<3/1440 -> TRUE | G18: =G5<3/1440 -> TRUE | H18: =H5<3/1440 -> TRUE | I18: =I5<3/1440 -> TRUE | J18: =J5<3/1440 -> TRUE | ... Q18: =Q5<3/1440 -> TRUE
A19: 7900 | B19: Nijverdal | C19: =C6<3/1440 -> TRUE | D19: =D6<3/1440 -> TRUE | E19: =E6<3/1440 -> TRUE | F19: =F6<3/1440 -> TRUE | G19: =G6<3/1440 -> TRUE | H19: =H6<3/1440 -> TRUE | I19: =I6<3/1440 -> TRUE | J19: =J6<3/1440 -> TRUE | ... Q19: =Q6<3/1440 -> TRUE
A20: 31300 | B20: Amersfoort | C20: =C7<3/1440 -> TRUE | D20: =D7<3/1440 -> TRUE | E20: =E7<3/1440 -> TRUE | F20: =F7<3/1440 -> TRUE | G20: =G7<3/1440 -> TRUE | H20: =H7<3/1440 -> TRUE | I20: =I7<3/1440 -> TRUE | J20: =J7<3/1440 -> TRUE | ... Q20: =Q7<3/1440 -> TRUE
A21: 3600 | B21: Zwolle | C21: =C8<3/1440 -> FALSE | D21: =D8<3/1440 -> FALSE | E21: =E8<3/1440 -> FALSE | F21: =F8<3/1440 -> TRUE | G21: =G8<3/1440 -> TRUE | H21: =H8<3/1440 -> TRUE | I21: =I8<3/1440 -> TRUE | J21: =J8<3/1440 -> TRUE | ... Q21: =Q8<3/1440 -> TRUE
A22: 20350 | B22: Hengelo | C22: =C9<3/1440 -> TRUE | D22: =D9<3/1440 -> TRUE | E22: =E9<3/1440 -> TRUE | F22: =F9<3/1440 -> TRUE | G22: =G9<3/1440 -> TRUE | H22: =H9<3/1440 -> TRUE | I22: =I9<3/1440 -> TRUE | J22: =J9<3/1440 -> TRUE | ... Q22: =Q9<3/1440 -> TRUE
A23: 31200 | B23: Hengelo | C23: =C10<3/1440 -> FALSE | D23: =D10<3/1440 -> FALSE | E23: =E10<3/1440 -> FALSE | F23: =F10<3/1440 -> TRUE | G23: =G10<3/1440 -> TRUE | H23: =H10<3/1440 -> TRUE | I23: =I10<3/1440 -> TRUE | J23: =J10<3/1440 -> TRUE | ... Q23: =Q10<3/1440 -> TRUE
A24: 31200 | B24: Zutphen | C24: =C10<3/1440 -> FALSE | D24: =D10<3/1440 -> FALSE | E24: =E10<3/1440 -> FALSE | F24: =F10<3/1440 -> TRUE | G24: =G10<3/1440 -> TRUE | H24: =H10<3/1440 -> TRUE | I24: =I10<3/1440 -> TRUE | J24: =J10<3/1440 -> TRUE | ... Q24: =Q10<3/1440 -> TRUE
A25: 7900 | B25: Zwolle | C25: =C12<3/1440 -> TRUE | D25: =D12<3/1440 -> TRUE | E25: =E12<3/1440 -> TRUE | F25: =F12<3/1440 -> TRUE | G25: =G12<3/1440 -> TRUE | H25: =H12<3/1440 -> TRUE | I25: =I12<3/1440 -> TRUE | J25: =J12<3/1440 -> TRUE | ... Q25: =Q12<3/1440 -> TRUE
A26: Punctuality | C26: =COUNTIF(C16:C21,TRUE) / 6 -> 0.66666667 | D26: =COUNTIF(D16:D21,TRUE) / 6 -> 0.33333333 | E26: =COUNTIF(E16:E21,TRUE) / 6 -> 0.33333333 | F26: =COUNTIF(F16:F21,TRUE) / 6 -> 0.83333333 | G26: =COUNTIF(G16:G21,TRUE) / 6 -> 0.83333333 | H26: =COUNTIF(H16:H21,TRUE) / 6 -> 0.83333333 | I26: =COUNTIF(I16:I21,TRUE) / 6 -> 0.83333333 | J26: =COUNTIF(J16:J21,TRUE) / 6 -> 0.83333333 | ... Q26: =COUNTIF(Q16:Q21,TRUE) / 6 -> 1
A28: Diff ICE delay BB and Amf | C28: =C2-C1 -> -0.0020833333 | D28: =D2-D1 -> -0.0027777778 | E28: =E2-E1 -> -0.0029861111 | F28: =F2-F1 -> 0.0055324074 | G28: =G2-G1 -> 0.004837963 | H28: =H2-H1 -> 0.0041435185 | I28: =I2-I1 -> 0.0034490741 | J28: =J2-J1 -> 0.0027546296 | ... Q28: =Q2-Q1 -> 0.00023148148 | R28: Extra delay
A29: Diff ICE delay BB and Amf | C29: =C1-C2 -> 0.0020833333 | D29: =D1-D2 -> 0.0027777778 | E29: =E1-E2 -> 0.0029861111 | F29: =F1-F2 -> -0.0055324074 | G29: =G1-G2 -> -0.004837963 | H29: =H1-H2 -> -0.0041435185 | I29: =I1-I2 -> -0.0034490741 | J29: =J1-J2 -> -0.0027546296 | ... Q29: =Q1-Q2 -> -0.00023148148 | R29: Less delay
A31: Regional transfer | C31: =(C20+C21+C23+C24+C25)/5 -> 0.4 | D31: =(D20+D21+D23+D24+D25)/5 -> 0.4 | E31: =(E20+E21+E23+E24+E25)/5 -> 0.4 | F31: =(F20+F21+F23+F24+F25)/5 -> 1 | G31: =(G20+G21+G23+G24+G25)/5 -> 1 | H31: =(H20+H21+H23+H24+H25)/5 -> 1 | I31: =(I20+I21+I23+I24+I25)/5 -> 1 | J31: =(J20+J21+J23+J24+J25)/5 -> 1 | ... Q31: =(Q20+Q21+Q23+Q24+Q25)/5 -> 1

Sheet Stop Waits
A1: ICE Delay Odzg | C1: 0.0020833333 | D1: 0.0027777778 | E1: 0.0034722222 | F1: 0.0041666667 | G1: 0.0048611111 | H1: 0.0055555556 | I1: 0.00625 | J1: 0.0069444444 | K1: 0.0076388889 | L1: 0.0083333333 | M1: 0.0090277778 | N1: 0.0097222222 | O1: 0.010416667 | P1: 0.013888889 | Q1: 0.017361111 | R1: Originele vertrektijd Odzg = 09:56:06
A2: 140/240 | B2: Amersfoort | C2: 0 | D2: 0 | E2: 0.00046296296 | F2: 0.00016203704 | G2: 0.00085648148 | H2: 0.0019675926 | I2: 0.0022453704 | J2: 0.0096990741 | K2: 0.0096990741 | L2: 0.0096990741 | M2: 0.0096990741 | N2: 0.0096990741 | O2: 0.0096990741 | P2: 0.017592593 | Q2: 0.017592593 | R2: A140-late | T2: Originele aankomst Amf = 10:24:00
A3: 1700 | B3: Utrecht | C3: 0.00085648148 | D3: 0.0015740741 | E3: 0.0022685185 | F3: 0.002962963 | G3: 0.011365741 | H3: 0.011365741 | I3: 0.011365741 | J3: 0.0036805556 | K3: 0.0061111111 | L3: 0.0061111111 | M3: 0.011365741 | N3: 0.0061111111 | O3: 0.0037268519 | P3: 0.0015509259 | Q3: 0.0015509259 | R3: C1700-17
A4: 7000 | B4: Apeldoorn | C4: 0.00069444444 | D4: 0.0013888889 | E4: 0.0020833333 | F4: 0.0027777778 | G4: 0.0034722222 | H4: 0.0041666667 | I4: 0.0048611111 | J4: 0 | K4: 0 | L4: 0 | M4: 0 | N4: 0 | O4: 0 | P4: 0.0013657407 | Q4: 0.0013657407 | R4: A7000-15
A5: 31200 | B5: Goor | C5: 0.00055555556 | D5: 0.00125 | E5: 0.0028703704 | F5: 0.0028703704 | G5: 0.0033333333 | H5: 0.0040277778 | I5: 0.0047222222 | J5: 0.010162037 | K5: 0.010162037 | L5: 0.019675926 | M5: 0.019675926 | N5: 0.019675926 | O5: 0.019675926 | P5: 0.019675926 | Q5: 0.019675926 | R5: D31200-18
A6: 7900 | B6: Nijverdal | C6: 0 | D6: 0.00037037037 | E6: 0.0010648148 | F6: 0.0017592593 | G6: 0.0024537037 | H6: 0.0031481481 | I6: 0.0038425926 | J6: 0.004537037 | K6: 0.0052314815 | L6: 0.0052083333 | M6: 0.011435185 | N6: 0.0028009259 | O6: 0 | P6: 0 | Q6: 0 | R6: A7900-17
A7: 31300 | B7: Amersfoort | C7: 0 | D7: 0 | E7: 0 | F7: 0 | G7: 0 | H7: 0.00092592593 | I7: 0.0012037037 | J7: 0 | K7: 0 | L7: 0 | M7: 0 | N7: 0 | O7: 0 | P7: 0 | Q7: 0 | R7: A31300-19
A8: 3600 | B8: Zwolle | C8: 0.002337963 | D8: 0.0039814815 | E8: 0.0046759259 | F8: 0.0053703704 | G8: 0.0060648148 | H8: 0.00094907407 | I8: 0.00094907407 | J8: 0.00094907407 | K8: 0.00094907407 | L8: 0.00094907407 | M8: 0.00094907407 | N8: 0.00094907407 | O8: 0.00094907407 | P8: 0.00094907407 | Q8: 0.00094907407
A9: 20350 | B9: Hengelo | C9: 0 | D9: 0 | E9: 0 | F9: 0 | G9: 0 | H9: 0 | I9: 0 | J9: 0 | K9: 0 | L9: 0 | M9: 0 | N9: 0 | O9: 0.00069444444 | P9: 0 | Q9: 0 | R9: B36100-18
A10: 31200 | B10: Hengelo | C10: 0.0021990741 | D10: 0.0028935185 | E10: 0.003587963 | F10: 0.0042824074 | G10: 0.0049768519 | H10: 0.0056712963 | I10: 0.0063657407 | J10: 0.0070601852 | K10: 0.0077546296 | L10: 0.016041667 | M10: 0.013703704 | N10: 0.015069444 | O10: 0.015069444 | P10: 0.016203704 | Q10: 0.017476852
A11: 31200 | B11: Zutphen | C11: 0.00016203704 | D11: 0.00027777778 | E11: 0.001875 | F11: 0.001875 | G11: 0.002337963 | H11: 0.0030324074 | I11: 0.0081944444 | J11: 0.0091666667 | K11: 0.0091666667 | L11: 0.019259259 | M11: 0.019259259 | N11: 0.019259259 | O11: 0.019259259 | P11: 0.019259259 | Q11: 0.019259259
A12: 7900 | B12: Zwolle | C12: 0 | D12: 0 | E12: 0 | F12: 0 | G12: 0 | H12: 0 | I12: 2.3148148e-05 | J12: 0.00071759259 | K12: 0.001412037 | L12: 0.0013888889 | M12: 0.0076157407 | N12: 0 | O12: 0 | P12: 0 | Q12: 0
A13: Total delay all trains in the scope at the first hub outside the corridor | C13: =SUM(C3:C8) -> 0.0044444444 | D13: =SUM(D3:D8) -> 0.0085648148 | E13: =SUM(E3:E8) -> 0.012962963 | F13: =SUM(F3:F8) -> 0.015740741 | G13: =SUM(G3:G8) -> 0.026689815 | H13: =SUM(H3:H8) -> 0.024583333 | I13: =SUM(I3:I8) -> 0.026944444 | J13: =SUM(J3:J8) -> 0.019328704 | ... Q13: =SUM(Q3:Q8) -> 0.023541667
A15: 140/240 | B15: Amersfoort | C15: =C2<6/1440 -> TRUE | D15: =D2<6/1440 -> TRUE | E15: =E2<6/1440 -> TRUE | F15: =F2<6/1440 -> TRUE | G15: =G2<6/1440 -> TRUE | H15: =H2<6/1440 -> TRUE | I15: =I2<6/1440 -> TRUE | J15: =J2<6/1440 -> FALSE | ... Q15: =Q2<6/1440 -> FALSE
A16: 1700 | B16: Utrecht | C16: =C3<3/1440 -> TRUE | D16: =D3<3/1440 -> TRUE | E16: =E3<3/1440 -> FALSE | F16: =F3<3/1440 -> FALSE | G16: =G3<3/1440 -> FALSE | H16: =H3<3/1440 -> FALSE | I16: =I3<3/1440 -> FALSE | J16: =J3<3/1440 -> FALSE | ... Q16: =Q3<3/1440 -> TRUE
A17: 7000 | B17: Apeldoorn | C17: =C4<3/1440 -> TRUE | D17: =D4<3/1440 -> TRUE | E17: =E4<3/1440 -> FALSE | F17: =F4<3/1440 -> FALSE | G17: =G4<3/1440 -> FALSE | H17: =H4<3/1440 -> FALSE | I17: =I4<3/1440 -> FALSE | J17: =J4<3/1440 -> TRUE | ... Q17: =Q4<3/1440 -> TRUE
A18: 31200 | B18: Goor | C18: =C5<3/1440 -> TRUE | D18: =D5<3/1440 -> TRUE | E18: =E5<3/1440 -> FALSE | F18: =F5<3/1440 -> FALSE | G18: =G5<3/1440 -> FALSE | H18: =H5<3/1440 -> FALSE | I18: =I5<3/1440 -> FALSE | J18: =J5<3/1440 -> FALSE | ... Q18: =Q5<3/1440 -> FALSE
A19: 7900 | B19: Nijverdal | C19: =C6<3/1440 -> TRUE | D19: =D6<3/1440 -> TRUE | E19: =E6<3/1440 -> TRUE | F19: =F6<3/1440 -> TRUE | G19: =G6<3/1440 -> FALSE | H19: =H6<3/1440 -> FALSE | I19: =I6<3/1440 -> FALSE | J19: =J6<3/1440 -> FALSE | ... Q19: =Q6<3/1440 -> TRUE
A20: 31300 | B20: Amersfoort | C20: =C7<3/1440 -> TRUE | D20: =D7<3/1440 -> TRUE | E20: =E7<3/1440 -> TRUE | F20: =F7<3/1440 -> TRUE | G20: =G7<3/1440 -> TRUE | H20: =H7<3/1440 -> TRUE | I20: =I7<3/1440 -> TRUE | J20: =J7<3/1440 -> TRUE | ... Q20: =Q7<3/1440 -> TRUE
A21: 3600 | B21: Zwolle | C21: =C8<3/1440 -> FALSE | D21: =D8<3/1440 -> FALSE | E21: =E8<3/1440 -> FALSE | F21: =F8<3/1440 -> FALSE | G21: =G8<3/1440 -> FALSE | H21: =H8<3/1440 -> TRUE | I21: =I8<3/1440 -> TRUE | J21: =J8<3/1440 -> TRUE | ... Q21: =Q8<3/1440 -> TRUE
A22: 20350 | B22: Hengelo | C22: =C9<3/1440 -> TRUE | D22: =D9<3/1440 -> TRUE | E22: =E9<3/1440 -> TRUE | F22: =F9<3/1440 -> TRUE | G22: =G9<3/1440 -> TRUE | H22: =H9<3/1440 -> TRUE | I22: =I9<3/1440 -> TRUE | J22: =J9<3/1440 -> TRUE | ... Q22: =Q9<3/1440 -> TRUE
A23: 31200 | B23: Hengelo | C23: =C10<3/1440 -> FALSE | D23: =D10<3/1440 -> FALSE | E23: =E10<3/1440 -> FALSE | F23: =F10<3/1440 -> FALSE | G23: =G10<3/1440 -> FALSE | H23: =H10<3/1440 -> FALSE | I23: =I10<3/1440 -> FALSE | J23: =J10<3/1440 -> FALSE | ... Q23: =Q10<3/1440 -> FALSE
A24: 31200 | B24: Zutphen | C24: =C10<3/1440 -> FALSE | D24: =D10<3/1440 -> FALSE | E24: =E10<3/1440 -> FALSE | F24: =F10<3/1440 -> FALSE | G24: =G10<3/1440 -> FALSE | H24: =H10<3/1440 -> FALSE | I24: =I10<3/1440 -> FALSE | J24: =J10<3/1440 -> FALSE | ... Q24: =Q10<3/1440 -> FALSE
A25: 7900 | B25: Zwolle | C25: =C12<3/1440 -> TRUE | D25: =D12<3/1440 -> TRUE | E25: =E12<3/1440 -> TRUE | F25: =F12<3/1440 -> TRUE | G25: =G12<3/1440 -> TRUE | H25: =H12<3/1440 -> TRUE | I25: =I12<3/1440 -> TRUE | J25: =J12<3/1440 -> TRUE | ... Q25: =Q12<3/1440 -> TRUE
A26: Punctuality | C26: =COUNTIF(C16:C21,TRUE) / 6 -> 0.83333333 | D26: =COUNTIF(D16:D21,TRUE) / 6 -> 0.83333333 | E26: =COUNTIF(E16:E21,TRUE) / 6 -> 0.33333333 | F26: =COUNTIF(F16:F21,TRUE) / 6 -> 0.33333333 | G26: =COUNTIF(G16:G21,TRUE) / 6 -> 0.16666667 | H26: =COUNTIF(H16:H21,TRUE) / 6 -> 0.33333333 | I26: =COUNTIF(I16:I21,TRUE) / 6 -> 0.33333333 | J26: =COUNTIF(J16:J21,TRUE) / 6 -> 0.5 | ... Q26: =COUNTIF(Q16:Q21,TRUE) / 6 -> 0.83333333
A28: Diff ICE delay BB and Amf | C28: =C2-C1 -> -0.0020833333 | D28: =D2-D1 -> -0.0027777778 | E28: =E2-E1 -> -0.0030092593 | F28: =F2-F1 -> -0.0040046296 | G28: =G2-G1 -> -0.0040046296 | H28: =H2-H1 -> -0.003587963 | I28: =I2-I1 -> -0.0040046296 | J28: =J2-J1 -> 0.0027546296 | ... Q28: =Q2-Q1 -> 0.00023148148 | R28: Extra delay
A29: Diff ICE delay BB and Amf | C29: =C1-C2 -> 0.0020833333 | D29: =D1-D2 -> 0.0027777778 | E29: =E1-E2 -> 0.0030092593 | F29: =F1-F2 -> 0.0040046296 | G29: =G1-G2 -> 0.0040046296 | H29: =H1-H2 -> 0.003587963 | I29: =I1-I2 -> 0.0040046296 | J29: =J1-J2 -> -0.0027546296 | ... Q29: =Q1-Q2 -> -0.00023148148 | R29: Less delay
A31: Regional transfer | C31: =(C20+C21+C23+C24+C25)/5 -> 0.4 | D31: =(D20+D21+D23+D24+D25)/5 -> 0.4 | E31: =(E20+E21+E23+E24+E25)/5 -> 0.4 | F31: =(F20+F21+F23+F24+F25)/5 -> 0.4 | G31: =(G20+G21+G23+G24+G25)/5 -> 0.4 | H31: =(H20+H21+H23+H24+H25)/5 -> 0.6 | I31: =(I20+I21+I23+I24+I25)/5 -> 0.6 | J31: =(J20+J21+J23+J24+J25)/5 -> 0.6 | ... Q31: =(Q20+Q21+Q23+Q24+Q25)/5 -> 0.6

Sheet Remove stop Hengelo
A1: ICE Delay Odzg | C1: 0.0020833333 | D1: 0.0027777778 | E1: 0.0034722222 | F1: 0.0041666667 | G1: 0.0048611111 | H1: 0.0055555556 | I1: 0.00625 | J1: 0.0069444444 | K1: 0.0076388889 | L1: 0.0083333333 | M1: 0.0090277778 | N1: 0.0097222222 | O1: 0.010416667 | P1: 0.013888889 | Q1: 0.017361111 | R1: Originele vertrektijd Odzg = 09:56:06
A2: 140/240 | B2: Amersfoort | C2: 0 | D2: 0 | E2: 0 | F2: 0 | G2: 0.00041666667 | H2: 0.00046296296 | I2: 0.00092592593 | J2: 0.0096990741 | K2: 0.0096990741 | L2: 0.0096990741 | M2: 0.0096990741 | N2: 0.0096990741 | O2: 0.0096990741 | P2: 0.011435185 | Q2: 0.017592593 | R2: A140-late | T2: Originele aankomst Amf = 10:24:00
A3: 1700 | B3: Utrecht | C3: 0 | D3: 0.00011574074 | E3: 0.00083333333 | F3: 0.0016435185 | G3: 0.0032175926 | H3: 0.0032638889 | I3: 0.011365741 | J3: 0.0037268519 | K3: 0.0037268519 | L3: 0.0061111111 | M3: 0.0061111111 | N3: 0.0037268519 | O3: 0.0037268519 | P3: 0.0062037037 | Q3: 0.0015509259 | R3: C1700-17
A4: 7000 | B4: Apeldoorn | C4: 0 | D4: 6.9444444e-05 | E4: 0.00076388889 | F4: 0.0014583333 | G4: 0.0030324074 | H4: 0.0030787037 | I4: 0.0035416667 | J4: 0 | K4: 0 | L4: 0 | M4: 0 | N4: 0 | O4: 0 | P4: 0.0013657407 | Q4: 0.0013657407 | R4: A7000-15
A5: 31200 | B5: Goor | C5: 0.00055555556 | D5: 0.00125 | E5: 0.0028703704 | F5: 0.0028703704 | G5: 0 | H5: 0 | I5: 0 | J5: 0 | K5: 0 | L5: 0 | M5: 0 | N5: 0 | O5: 0 | P5: 0 | Q5: 0 | R5: D31200-18
A6: 7900 | B6: Nijverdal | C6: 0 | D6: 0.00037037037 | E6: 0.0010648148 | F6: 0.0017592593 | G6: 0.0012962963 | H6: 0.0013425926 | I6: 0.0018055556 | J6: 0.0025 | K6: 0.0031944444 | L6: 0.0038888889 | M6: 0.0045833333 | N6: 0.0015740741 | O6: 0.0021759259 | P6: 0 | Q6: 0 | R6: A7900-17
A7: 31300 | B7: Amersfoort | C7: 0 | D7: 0 | E7: 0 | F7: 0 | G7: 0 | H7: 0 | I7: 0 | J7: 0 | K7: 0 | L7: 0 | M7: 0 | N7: 0 | O7: 0 | P7: 0 | Q7: 0 | R7: A31300-19
A8: 3600 | B8: Zwolle | C8: 0.0010648148 | D8: 0.0017361111 | E8: 0.0024074074 | F8: 0.0040509259 | G8: 0.005625 | H8: 0.0056712963 | I8: 0.0061342593 | J8: 0.00094907407 | K8: 0.00094907407 | L8: 0.00094907407 | M8: 0.00094907407 | N8: 0.00094907407 | O8: 0.00094907407 | P8: 0.00094907407 | Q8: 0.00094907407
A9: 20350 | B9: Hengelo | C9: 0 | D9: 0 | E9: 0 | F9: 0 | G9: 0 | H9: 0 | I9: 0 | J9: 0 | K9: 0 | L9: 0 | M9: 0 | N9: 0 | O9: 0.00069444444 | P9: 0 | Q9: 0 | R9: B36100-18
A10: 31200 | B10: Hengelo | C10: 0.0021990741 | D10: 0.0028935185 | E10: 0.003587963 | F10: 0.0042824074 | G10: 0.00011574074 | H10: 0.00011574074 | I10: 0.00011574074 | J10: 0.00011574074 | K10: 0.00011574074 | L10: 0.00011574074 | M10: 0.00011574074 | N10: 0.00011574074 | O10: 0.00011574074 | P10: 0.00011574074 | Q10: 0.00011574074
A11: 31200 | B11: Zutphen | C11: 0.00016203704 | D11: 0.00027777778 | E11: 0.001875 | F11: 0.001875 | G11: 0.00016203704 | H11: 0.00016203704 | I11: 0.00016203704 | J11: 0.00016203704 | K11: 0.00016203704 | L11: 0.00016203704 | M11: 0.00016203704 | N11: 0.00016203704 | O11: 0.00016203704 | P11: 0.00016203704 | Q11: 0.00016203704
A12: 7900 | B12: Zwolle | C12: 0 | D12: 0 | E12: 0 | F12: 0 | G12: 0 | H12: 0 | I12: 0 | J12: 0 | K12: 0 | L12: 6.9444444e-05 | M12: 0.00076388889 | N12: 0 | O12: 0 | P12: 0 | Q12: 0
A13: Total delay all trains in the scope at the first hub outside the corridor | C13: =SUM(C3:C8) -> 0.0016203704 | D13: =SUM(D3:D8) -> 0.0035416667 | E13: =SUM(E3:E8) -> 0.0079398148 | F13: =SUM(F3:F8) -> 0.011782407 | G13: =SUM(G3:G8) -> 0.013171296 | H13: =SUM(H3:H8) -> 0.013356481 | I13: =SUM(I3:I8) -> 0.022847222 | J13: =SUM(J3:J8) -> 0.0071759259 | ... Q13: =SUM(Q3:Q8) -> 0.0038657407
A15: 140/240 | B15: Amersfoort | C15: =C2<6/1440 -> TRUE | D15: =D2<6/1440 -> TRUE | E15: =E2<6/1440 -> TRUE | F15: =F2<6/1440 -> TRUE | G15: =G2<6/1440 -> TRUE | H15: =H2<6/1440 -> TRUE | I15: =I2<6/1440 -> TRUE | J15: =J2<6/1440 -> FALSE | ... Q15: =Q2<6/1440 -> FALSE
A16: 1700 | B16: Utrecht | C16: =C3<3/1440 -> TRUE | D16: =D3<3/1440 -> TRUE | E16: =E3<3/1440 -> TRUE | F16: =F3<3/1440 -> TRUE | G16: =G3<3/1440 -> FALSE | H16: =H3<3/1440 -> FALSE | I16: =I3<3/1440 -> FALSE | J16: =J3<3/1440 -> FALSE | ... Q16: =Q3<3/1440 -> TRUE
A17: 7000 | B17: Apeldoorn | C17: =C4<3/1440 -> TRUE | D17: =D4<3/1440 -> TRUE | E17: =E4<3/1440 -> TRUE | F17: =F4<3/1440 -> TRUE | G17: =G4<3/1440 -> FALSE | H17: =H4<3/1440 -> FALSE | I17: =I4<3/1440 -> FALSE | J17: =J4<3/1440 -> TRUE | ... Q17: =Q4<3/1440 -> TRUE
A18: 31200 | B18: Goor | C18: =C5<3/1440 -> TRUE | D18: =D5<3/1440 -> TRUE | E18: =E5<3/1440 -> FALSE | F18: =F5<3/1440 -> FALSE | G18: =G5<3/1440 -> TRUE | H18: =H5<3/1440 -> TRUE | I18: =I5<3/1440 -> TRUE | J18: =J5<3/1440 -> TRUE | ... Q18: =Q5<3/1440 -> TRUE
A19: 7900 | B19: Nijverdal | C19: =C6<3/1440 -> TRUE | D19: =D6<3/1440 -> TRUE | E19: =E6<3/1440 -> TRUE | F19: =F6<3/1440 -> TRUE | G19: =G6<3/1440 -> TRUE | H19: =H6<3/1440 -> TRUE | I19: =I6<3/1440 -> TRUE | J19: =J6<3/1440 -> FALSE | ... Q19: =Q6<3/1440 -> TRUE
A20: 31300 | B20: Amersfoort | C20: =C7<3/1440 -> TRUE | D20: =D7<3/1440 -> TRUE | E20: =E7<3/1440 -> TRUE | F20: =F7<3/1440 -> TRUE | G20: =G7<3/1440 -> TRUE | H20: =H7<3/1440 -> TRUE | I20: =I7<3/1440 -> TRUE | J20: =J7<3/1440 -> TRUE | ... Q20: =Q7<3/1440 -> TRUE
A21: 3600 | B21: Zwolle | C21: =C8<3/1440 -> TRUE | D21: =D8<3/1440 -> TRUE | E21: =E8<3/1440 -> FALSE | F21: =F8<3/1440 -> FALSE | G21: =G8<3/1440 -> FALSE | H21: =H8<3/1440 -> FALSE | I21: =I8<3/1440 -> FALSE | J21: =J8<3/1440 -> TRUE | ... Q21: =Q8<3/1440 -> TRUE
A22: 20350 | B22: Hengelo | C22: =C9<3/1440 -> TRUE | D22: =D9<3/1440 -> TRUE | E22: =E9<3/1440 -> TRUE | F22: =F9<3/1440 -> TRUE | G22: =G9<3/1440 -> TRUE | H22: =H9<3/1440 -> TRUE | I22: =I9<3/1440 -> TRUE | J22: =J9<3/1440 -> TRUE | ... Q22: =Q9<3/1440 -> TRUE
A23: 31200 | B23: Hengelo | C23: =C10<3/1440 -> FALSE | D23: =D10<3/1440 -> FALSE | E23: =E10<3/1440 -> FALSE | F23: =F10<3/1440 -> FALSE | G23: =G10<3/1440 -> TRUE | H23: =H10<3/1440 -> TRUE | I23: =I10<3/1440 -> TRUE | J23: =J10<3/1440 -> TRUE | ... Q23: =Q10<3/1440 -> TRUE
A24: 31200 | B24: Zutphen | C24: =C11<3/1440 -> TRUE | D24: =D11<3/1440 -> TRUE | E24: =E11<3/1440 -> TRUE | F24: =F11<3/1440 -> TRUE | G24: =G11<3/1440 -> TRUE | H24: =H11<3/1440 -> TRUE | I24: =I11<3/1440 -> TRUE | J24: =J11<3/1440 -> TRUE | ... Q24: =Q11<3/1440 -> TRUE
A25: 7900 | B25: Zwolle | C25: =C12<3/1440 -> TRUE | D25: =D12<3/1440 -> TRUE | E25: =E12<3/1440 -> TRUE | F25: =F12<3/1440 -> TRUE | G25: =G12<3/1440 -> TRUE | H25: =H12<3/1440 -> TRUE | I25: =I12<3/1440 -> TRUE | J25: =J12<3/1440 -> TRUE | ... Q25: =Q12<3/1440 -> TRUE
A26: Punctuality | C26: =COUNTIF(C16:C21,TRUE) / 6 -> 1 | D26: =COUNTIF(D16:D21,TRUE) / 6 -> 1 | E26: =COUNTIF(E16:E21,TRUE) / 6 -> 0.66666667 | F26: =COUNTIF(F16:F21,TRUE) / 6 -> 0.66666667 | G26: =COUNTIF(G16:G21,TRUE) / 6 -> 0.5 | H26: =COUNTIF(H16:H21,TRUE) / 6 -> 0.5 | I26: =COUNTIF(I16:I21,TRUE) / 6 -> 0.5 | J26: =COUNTIF(J16:J21,TRUE) / 6 -> 0.66666667 | ... Q26: =COUNTIF(Q16:Q21,TRUE) / 6 -> 1
A28: Diff ICE delay BB and Amf | C28: =C2-C1 -> -0.0020833333 | D28: =D2-D1 -> -0.0027777778 | E28: =E2-E1 -> -0.0034722222 | F28: =F2-F1 -> -0.0041666667 | G28: =G2-G1 -> -0.0044444444 | H28: =H2-H1 -> -0.0050925926 | I28: =I2-I1 -> -0.0053240741 | J28: =J2-J1 -> 0.0027546296 | ... Q28: =Q2-Q1 -> 0.00023148148 | R28: Extra delay
A29: Diff ICE delay BB and Amf | C29: =C1-C2 -> 0.0020833333 | D29: =D1-D2 -> 0.0027777778 | E29: =E1-E2 -> 0.0034722222 | F29: =F1-F2 -> 0.0041666667 | G29: =G1-G2 -> 0.0044444444 | H29: =H1-H2 -> 0.0050925926 | I29: =I1-I2 -> 0.0053240741 | J29: =J1-J2 -> -0.0027546296 | ... Q29: =Q1-Q2 -> -0.00023148148 | R29: Less delay
A31: Regional transfer | C31: =(C20+C21+C23+C24+C25)/5 -> 0.8 | D31: =(D20+D21+D23+D24+D25)/5 -> 0.8 | E31: =(E20+E21+E23+E24+E25)/5 -> 0.6 | F31: =(F20+F21+F23+F24+F25)/5 -> 0.6 | G31: =(G20+G21+G23+G24+G25)/5 -> 0.8 | H31: =(H20+H21+H23+H24+H25)/5 -> 0.8 | I31: =(I20+I21+I23+I24+I25)/5 -> 0.8 | J31: =(J20+J21+J23+J24+J25)/5 -> 1 | ... Q31: =(Q20+Q21+Q23+Q24+Q25)/5 -> 1

Sheet Extra platform Hengelo
A1: ICE Delay Odzg | C1: 0.0020833333 | D1: 0.0027777778 | E1: 0.0034722222 | F1: 0.0041666667 | G1: 0.0048611111 | H1: 0.0055555556 | I1: 0.00625 | J1: 0.0069444444 | K1: 0.0076388889 | L1: 0.0083333333 | M1: 0.0090277778 | N1: 0.0097222222 | O1: 0.010416667 | P1: 0.013888889 | Q1: 0.017361111 | R1: Originele vertrektijd Odzg = 09:56:06
A2: 140/240 | B2: Amersfoort | C2: 0 | D2: 0 | E2: 0 | F2: 0.00016203704 | G2: 0.002037037 | H2: 0.0020601852 | I2: 0.0022453704 | J2: 0.0096990741 | K2: 0.0096990741 | L2: 0.0096990741 | M2: 0.0096990741 | N2: 0.0096990741 | O2: 0.0096990741 | P2: 0.017592593 | Q2: 0.017592593 | R2: A140-late | T2: Originele aankomst Amf = 10:24:00 | X2: 0.48469907
A3: 1700 | B3: Utrecht | C3: 0.00074074074 | D3: 0.0015509259 | E3: 0.0022685185 | F3: 0.002962963 | G3: 0.011365741 | H3: 0.011365741 | I3: 0.011365741 | J3: 0.0037268519 | K3: 0.0036805556 | L3: 0.0061111111 | M3: 0.011365741 | N3: 0.0061111111 | O3: 0.0037268519 | P3: 0.0015509259 | Q3: 0.0015509259 | R3: C1700-17
A4: 7000 | B4: Apeldoorn | C4: 0.00069444444 | D4: 0.0013888889 | E4: 0.0020833333 | F4: 0.0027777778 | G4: 0.0043518519 | H4: 0.0043981481 | I4: 0.0048611111 | J4: 0 | K4: 0 | L4: 0 | M4: 0 | N4: 0 | O4: 0 | P4: 0.0013657407 | Q4: 0.0013657407 | R4: A7000-15
A5: 31200 | B5: Goor | C5: 0.00055555556 | D5: 0.00125 | E5: 0.0028703704 | F5: 0.0028703704 | G5: 0 | H5: 0 | I5: 0 | J5: 0 | K5: 0 | L5: 0 | M5: 0 | N5: 0 | O5: 0 | P5: 0 | Q5: 0 | R5: D31200-18
A6: 7900 | B6: Nijverdal | C6: 0 | D6: 0.00037037037 | E6: 0.0010648148 | F6: 0.0017592593 | G6: 0.0026157407 | H6: 0.002662037 | I6: 0.0032407407 | J6: 0.0039351852 | K6: 0.0045138889 | L6: 0.0052083333 | M6: 0.011435185 | N6: 0.0028009259 | O6: 0 | P6: 0 | Q6: 0 | R6: A7900-17
A7: 31300 | B7: Amersfoort | C7: 0 | D7: 0 | E7: 0 | F7: 0 | G7: 0.00099537037 | H7: 0.0010185185 | I7: 0.0012037037 | J7: 0 | K7: 0 | L7: 0 | M7: 0 | N7: 0 | O7: 0 | P7: 0 | Q7: 0 | R7: A31300-19
A8: 3600 | B8: Zwolle | C8: 0.002337963 | D8: 0.0039814815 | E8: 0.0046759259 | F8: 0.0053703704 | G8: 0.00094907407 | H8: 0.00094907407 | I8: 0.00094907407 | J8: 0.00094907407 | K8: 0.00094907407 | L8: 0.00094907407 | M8: 0.00094907407 | N8: 0.00094907407 | O8: 0.00094907407 | P8: 0.00094907407 | Q8: 0.00094907407
A9: 20350 | B9: Hengelo | C9: 0 | D9: 0 | E9: 0 | F9: 0 | G9: 0 | H9: 0 | I9: 0 | J9: 0 | K9: 0 | L9: 0 | M9: 0 | N9: 0 | O9: 0.00069444444 | P9: 0 | Q9: 0 | R9: B36100-18
A10: 31200 | B10: Hengelo | C10: 0.0021990741 | D10: 0.0028935185 | E10: 0.003587963 | F10: 0.0042824074 | G10: 0.00011574074 | H10: 0.00011574074 | I10: 0.00011574074 | J10: 0.00011574074 | K10: 0.00011574074 | L10: 0.00011574074 | M10: 0.00011574074 | N10: 0.00011574074 | O10: 0.00011574074 | P10: 0.00011574074 | Q10: 0.00011574074
A11: 31200 | B11: Zutphen | C11: 0.00016203704 | D11: 0.00027777778 | E11: 0.001875 | F11: 0.001875 | G11: 0.00016203704 | H11: 0.00016203704 | I11: 0.00016203704 | J11: 0.00016203704 | K11: 0.00016203704 | L11: 0.00016203704 | M11: 0.00016203704 | N11: 0.00016203704 | O11: 0.00016203704 | P11: 0.00016203704 | Q11: 0.00016203704
A12: 7900 | B12: Zwolle | C12: 0 | D12: 0 | E12: 0 | F12: 0 | G12: 0 | H12: 0 | I12: 0 | J12: 0 | K12: 0.00069444444 | L12: 0.0013888889 | M12: 0.0076157407 | N12: 0 | O12: 0 | P12: 0 | Q12: 0
A13: Total delay all trains in the scope at the first hub outside the corridor | C13: =SUM(C3:C8) -> 0.0043287037 | D13: =SUM(D3:D8) -> 0.0085416667 | E13: =SUM(E3:E8) -> 0.012962963 | F13: =SUM(F3:F8) -> 0.015740741 | G13: =SUM(G3:G8) -> 0.020277778 | H13: =SUM(H3:H8) -> 0.020393519 | I13: =SUM(I3:I8) -> 0.02162037 | J13: =SUM(J3:J8) -> 0.0086111111 | ... Q13: =SUM(Q3:Q8) -> 0.0038657407
A15: 140/240 | B15: Amersfoort | C15: =C2<6/1440 -> TRUE | D15: =D2<6/1440 -> TRUE | E15: =E2<6/1440 -> TRUE | F15: =F2<6/1440 -> TRUE | G15: =G2<6/1440 -> TRUE | H15: =H2<6/1440 -> TRUE | I15: =I2<6/1440 -> TRUE | J15: =J2<6/1440 -> FALSE | ... Q15: =Q2<6/1440 -> FALSE
A16: 1700 | B16: Utrecht | C16: =C3<3/1440 -> TRUE | D16: =D3<3/1440 -> TRUE | E16: =E3<3/1440 -> FALSE | F16: =F3<3/1440 -> FALSE | G16: =G3<3/1440 -> FALSE | H16: =H3<3/1440 -> FALSE | I16: =I3<3/1440 -> FALSE | J16: =J3<3/1440 -> FALSE | ... Q16: =Q3<3/1440 -> TRUE
A17: 7000 | B17: Apeldoorn | C17: =C4<3/1440 -> TRUE | D17: =D4<3/1440 -> TRUE | E17: =E4<3/1440 -> FALSE | F17: =F4<3/1440 -> FALSE | G17: =G4<3/1440 -> FALSE | H17: =H4<3/1440 -> FALSE | I17: =I4<3/1440 -> FALSE | J17: =J4<3/1440 -> TRUE | ... Q17: =Q4<3/1440 -> TRUE
A18: 31200 | B18: Goor | C18: =C5<3/1440 -> TRUE | D18: =D5<3/1440 -> TRUE | E18: =E5<3/1440 -> FALSE | F18: =F5<3/1440 -> FALSE | G18: =G5<3/1440 -> TRUE | H18: =H5<3/1440 -> TRUE | I18: =I5<3/1440 -> TRUE | J18: =J5<3/1440 -> TRUE | ... Q18: =Q5<3/1440 -> TRUE
A19: 7900 | B19: Nijverdal | C19: =C6<3/1440 -> TRUE | D19: =D6<3/1440 -> TRUE | E19: =E6<3/1440 -> TRUE | F19: =F6<3/1440 -> TRUE | G19: =G6<3/1440 -> FALSE | H19: =H6<3/1440 -> FALSE | I19: =I6<3/1440 -> FALSE | J19: =J6<3/1440 -> FALSE | ... Q19: =Q6<3/1440 -> TRUE
A20: 31300 | B20: Amersfoort | C20: =C7<3/1440 -> TRUE | D20: =D7<3/1440 -> TRUE | E20: =E7<3/1440 -> TRUE | F20: =F7<3/1440 -> TRUE | G20: =G7<3/1440 -> TRUE | H20: =H7<3/1440 -> TRUE | I20: =I7<3/1440 -> TRUE | J20: =J7<3/1440 -> TRUE | ... Q20: =Q7<3/1440 -> TRUE
A21: 3600 | B21: Zwolle | C21: =C8<3/1440 -> FALSE | D21: =D8<3/1440 -> FALSE | E21: =E8<3/1440 -> FALSE | F21: =F8<3/1440 -> FALSE | G21: =G8<3/1440 -> TRUE | H21: =H8<3/1440 -> TRUE | I21: =I8<3/1440 -> TRUE | J21: =J8<3/1440 -> TRUE | ... Q21: =Q8<3/1440 -> TRUE
A22: 20350 | B22: Hengelo | C22: =C9<3/1440 -> TRUE | D22: =D9<3/1440 -> TRUE | E22: =E9<3/1440 -> TRUE | F22: =F9<3/1440 -> TRUE | G22: =G9<3/1440 -> TRUE | H22: =H9<3/1440 -> TRUE | I22: =I9<3/1440 -> TRUE | J22: =J9<3/1440 -> TRUE | ... Q22: =Q9<3/1440 -> TRUE
A23: 31200 | B23: Hengelo | C23: =C10<3/1440 -> FALSE | D23: =D10<3/1440 -> FALSE | E23: =E10<3/1440 -> FALSE | F23: =F10<3/1440 -> FALSE | G23: =G10<3/1440 -> TRUE | H23: =H10<3/1440 -> TRUE | I23: =I10<3/1440 -> TRUE | J23: =J10<3/1440 -> TRUE | ... Q23: =Q10<3/1440 -> TRUE
A24: 31200 | B24: Zutphen | C24: =C11<3/1440 -> TRUE | D24: =D11<3/1440 -> TRUE | E24: =E11<3/1440 -> TRUE | F24: =F11<3/1440 -> TRUE | G24: =G11<3/1440 -> TRUE | H24: =H11<3/1440 -> TRUE | I24: =I11<3/1440 -> TRUE | J24: =J11<3/1440 -> TRUE | ... Q24: =Q11<3/1440 -> TRUE
A25: 7900 | B25: Zwolle | C25: =C12<3/1440 -> TRUE | D25: =D12<3/1440 -> TRUE | E25: =E12<3/1440 -> TRUE | F25: =F12<3/1440 -> TRUE | G25: =G12<3/1440 -> TRUE | H25: =H12<3/1440 -> TRUE | I25: =I12<3/1440 -> TRUE | J25: =J12<3/1440 -> TRUE | ... Q25: =Q12<3/1440 -> TRUE
A26: Punctuality | C26: =COUNTIF(C16:C21,TRUE) / 6 -> 0.83333333 | D26: =COUNTIF(D16:D21,TRUE) / 6 -> 0.83333333 | E26: =COUNTIF(E16:E21,TRUE) / 6 -> 0.33333333 | F26: =COUNTIF(F16:F21,TRUE) / 6 -> 0.33333333 | G26: =COUNTIF(G16:G21,TRUE) / 6 -> 0.5 | H26: =COUNTIF(H16:H21,TRUE) / 6 -> 0.5 | I26: =COUNTIF(I16:I21,TRUE) / 6 -> 0.5 | J26: =COUNTIF(J16:J21,TRUE) / 6 -> 0.66666667 | ... Q26: =COUNTIF(Q16:Q21,TRUE) / 6 -> 1
A28: Diff ICE delay BB and Amf | C28: =C2-C1 -> -0.0020833333 | D28: =D2-D1 -> -0.0027777778 | E28: =E2-E1 -> -0.0034722222 | F28: =F2-F1 -> -0.0040046296 | G28: =G2-G1 -> -0.0028240741 | H28: =H2-H1 -> -0.0034953704 | I28: =I2-I1 -> -0.0040046296 | J28: =J2-J1 -> 0.0027546296 | ... Q28: =Q2-Q1 -> 0.00023148148 | R28: Extra delay
A29: Diff ICE delay BB and Amf | C29: =C1-C2 -> 0.0020833333 | D29: =D1-D2 -> 0.0027777778 | E29: =E1-E2 -> 0.0034722222 | F29: =F1-F2 -> 0.0040046296 | G29: =G1-G2 -> 0.0028240741 | H29: =H1-H2 -> 0.0034953704 | I29: =I1-I2 -> 0.0040046296 | J29: =J1-J2 -> -0.0027546296 | ... Q29: =Q1-Q2 -> -0.00023148148 | R29: Less delay
A31: Regional transfer | C31: =(C20+C21+C23+C24+C25)/5 -> 0.6 | D31: =(D20+D21+D23+D24+D25)/5 -> 0.6 | E31: =(E20+E21+E23+E24+E25)/5 -> 0.6 | F31: =(F20+F21+F23+F24+F25)/5 -> 0.6 | G31: =(G20+G21+G23+G24+G25)/5 -> 1 | H31: =(H20+H21+H23+H24+H25)/5 -> 1 | I31: =(I20+I21+I23+I24+I25)/5 -> 1 | J31: =(J20+J21+J23+J24+J25)/5 -> 1 | ... Q31: =(Q20+Q21+Q23+Q24+Q25)/5 -> 1

Sheet Short-turn Hengelo
A1: ICE Delay Odzg | C1: 0.0020833333 | D1: 0.0027777778 | E1: 0.0034722222 | F1: 0.0041666667 | G1: 0.0048611111 | H1: 0.0055555556 | I1: 0.00625 | J1: 0.0069444444 | K1: 0.0076388889 | L1: 0.0083333333 | M1: 0.0090277778 | N1: 0.0097222222 | O1: 0.010416667 | P1: 0.013888889 | Q1: 0.017361111 | R1: Originele vertrektijd Odzg = 09:56:06
A2: 140/240 | B2: Amersfoort | C2: - | D2: - | E2: - | F2: - | G2: - | H2: - | I2: - | J2: - | K2: - | L2: - | M2: - | N2: - | O2: - | P2: - | Q2: - | R2: A140-late | T2: ICE arriveert nooit in Amersfoort
A3: 1700 | B3: Utrecht | C3: 0.0018518519 | D3: 0.0018518519 | E3: 0.001087963 | F3: 0.0015277778 | G3: 0.011365741 | H3: 0.011365741 | I3: 0.011365741 | J3: 0.0020833333 | K3: 0.0020833333 | L3: 0.011365741 | M3: 0.011365741 | N3: 0.011365741 | O3: 0.011365741 | P3: 0.0015509259 | Q3: 0.0015509259 | R3: C1700-17
A4: 7000 | B4: Apeldoorn | C4: 0.0016666667 | D4: 0.0016666667 | E4: 0.00092592593 | F4: 0.0013657407 | G4: 0 | H4: 0 | I4: 0 | J4: 0 | K4: 0 | L4: 0 | M4: 0 | N4: 0 | O4: 0 | P4: 0.0013657407 | Q4: 0.0013657407 | R4: A7000-15
A5: 31200 | B5: Goor | C5: 0.00043981481 | D5: 0.00125 | E5: 0.0028703704 | F5: 0.0028703704 | G5: 0 | H5: 0 | I5: 0 | J5: 0 | K5: 0 | L5: 0 | M5: 0 | N5: 0 | O5: 0 | P5: 0 | Q5: 0 | R5: D31200-18
A6: 7900 | B6: Nijverdal | C6: 0 | D6: 0.00037037037 | E6: 0.0010648148 | F6: 0.0017592593 | G6: 0 | H6: 0 | I6: 0 | J6: 0 | K6: 0 | L6: 0 | M6: 0 | N6: 0 | O6: 0 | P6: 0 | Q6: 0 | R6: A7900-17
A7: 31300 | B7: Amersfoort | C7: 0 | D7: 0 | E7: 0 | F7: 0 | G7: 0 | H7: 0 | I7: 0 | J7: 0 | K7: 0 | L7: 0 | M7: 0 | N7: 0 | O7: 0 | P7: 0 | Q7: 0 | R7: A31300-19
A8: 3600 | B8: Zwolle | C8: 0.00094907407 | D8: 0.00094907407 | E8: 0.00094907407 | F8: 0.00094907407 | G8: 0.00094907407 | H8: 0.00094907407 | I8: 0.00094907407 | J8: 0.00094907407 | K8: 0.00094907407 | L8: 0.00094907407 | M8: 0.00094907407 | N8: 0.00094907407 | O8: 0.00094907407 | P8: 0.00094907407 | Q8: 0.00094907407
A9: 20350 | B9: Hengelo | C9: 0 | D9: 0 | E9: 0 | F9: 0 | G9: 0 | H9: 0 | I9: 0 | J9: 0 | K9: 0 | L9: 0 | M9: 0 | N9: 0 | O9: 0.00069444444 | P9: 0 | Q9: 0 | R9: B36100-18
A10: 31200 | B10: Hengelo | C10: 0.0023148148 | D10: 0.0028935185 | E10: 0.003587963 | F10: 0.0042824074 | G10: 0.00011574074 | H10: 0.00011574074 | I10: 0.00011574074 | J10: 0.00011574074 | K10: 0.00011574074 | L10: 0.00011574074 | M10: 0.00011574074 | N10: 0.00011574074 | O10: 0.00011574074 | P10: 0.00011574074 | Q10: 0.00011574074
A11: 31200 | B11: Zutphen | C11: 0.00016203704 | D11: 0.00027777778 | E11: 0.001875 | F11: 0.001875 | G11: 0.00016203704 | H11: 0.00016203704 | I11: 0.00016203704 | J11: 0.00016203704 | K11: 0.00016203704 | L11: 0.00016203704 | M11: 0.00016203704 | N11: 0.00016203704 | O11: 0.00016203704 | P11: 0.00016203704 | Q11: 0.00016203704
A12: 7900 | B12: Zwolle | C12: 0 | D12: 0 | E12: 0 | F12: 0 | G12: 0 | H12: 0 | I12: 0 | J12: 0 | K12: 0 | L12: 0 | M12: 0 | N12: 0 | O12: 0 | P12: 0 | Q12: 0
A13: Total delay all trains in the scope at the first hub outside the corridor | C13: =SUM(C3:C8) -> 0.0049074074 | D13: =SUM(D3:D8) -> 0.006087963 | E13: =SUM(E3:E8) -> 0.0068981481 | F13: =SUM(F3:F8) -> 0.0084722222 | G13: =SUM(G3:G8) -> 0.012314815 | H13: =SUM(H3:H8) -> 0.012314815 | I13: =SUM(I3:I8) -> 0.012314815 | J13: =SUM(J3:J8) -> 0.0030324074 | ... Q13: =SUM(Q3:Q8) -> 0.0038657407
A15: 140/240 | B15: Amersfoort | C15: =C2<6/1440 -> FALSE | D15: =D2<6/1440 -> FALSE | E15: =E2<6/1440 -> FALSE | F15: =F2<6/1440 -> FALSE | G15: =G2<6/1440 -> FALSE | H15: =H2<6/1440 -> FALSE | I15: =I2<6/1440 -> FALSE | J15: =J2<6/1440 -> FALSE | ... Q15: =Q2<6/1440 -> FALSE
A16: 1700 | B16: Utrecht | C16: =C3<3/1440 -> TRUE | D16: =D3<3/1440 -> TRUE | E16: =E3<3/1440 -> TRUE | F16: =F3<3/1440 -> TRUE | G16: =G3<3/1440 -> FALSE | H16: =H3<3/1440 -> FALSE | I16: =I3<3/1440 -> FALSE | J16: =J3<3/1440 -> FALSE | ... Q16: =Q3<3/1440 -> TRUE
A17: 7000 | B17: Apeldoorn | C17: =C4<3/1440 -> TRUE | D17: =D4<3/1440 -> TRUE | E17: =E4<3/1440 -> TRUE | F17: =F4<3/1440 -> TRUE | G17: =G4<3/1440 -> TRUE | H17: =H4<3/1440 -> TRUE | I17: =I4<3/1440 -> TRUE | J17: =J4<3/1440 -> TRUE | ... Q17: =Q4<3/1440 -> TRUE
A18: 31200 | B18: Goor | C18: =C5<3/1440 -> TRUE | D18: =D5<3/1440 -> TRUE | E18: =E5<3/1440 -> FALSE | F18: =F5<3/1440 -> FALSE | G18: =G5<3/1440 -> TRUE | H18: =H5<3/1440 -> TRUE | I18: =I5<3/1440 -> TRUE | J18: =J5<3/1440 -> TRUE | ... Q18: =Q5<3/1440 -> TRUE
A19: 7900 | B19: Nijverdal | C19: =C6<3/1440 -> TRUE | D19: =D6<3/1440 -> TRUE | E19: =E6<3/1440 -> TRUE | F19: =F6<3/1440 -> TRUE | G19: =G6<3/1440 -> TRUE | H19: =H6<3/1440 -> TRUE | I19: =I6<3/1440 -> TRUE | J19: =J6<3/1440 -> TRUE | ... Q19: =Q6<3/1440 -> TRUE
A20: 31300 | B20: Amersfoort | C20: =C7<3/1440 -> TRUE | D20: =D7<3/1440 -> TRUE | E20: =E7<3/1440 -> TRUE | F20: =F7<3/1440 -> TRUE | G20: =G7<3/1440 -> TRUE | H20: =H7<3/1440 -> TRUE | I20: =I7<3/1440 -> TRUE | J20: =J7<3/1440 -> TRUE | ... Q20: =Q7<3/1440 -> TRUE
A21: 3600 | B21: Zwolle | C21: =C8<3/1440 -> TRUE | D21: =D8<3/1440 -> TRUE | E21: =E8<3/1440 -> TRUE | F21: =F8<3/1440 -> TRUE | G21: =G8<3/1440 -> TRUE | H21: =H8<3/1440 -> TRUE | I21: =I8<3/1440 -> TRUE | J21: =J8<3/1440 -> TRUE | ... Q21: =Q8<3/1440 -> TRUE
A22: 20350 | B22: Hengelo | C22: =C9<3/1440 -> TRUE | D22: =D9<3/1440 -> TRUE | E22: =E9<3/1440 -> TRUE | F22: =F9<3/1440 -> TRUE | G22: =G9<3/1440 -> TRUE | H22: =H9<3/1440 -> TRUE | I22: =I9<3/1440 -> TRUE | J22: =J9<3/1440 -> TRUE | ... Q22: =Q9<3/1440 -> TRUE
A23: 31200 | B23: Hengelo | C23: =C10<3/1440 -> FALSE | D23: =D10<3/1440 -> FALSE | E23: =E10<3/1440 -> FALSE | F23: =F10<3/1440 -> FALSE | G23: =G10<3/1440 -> TRUE | H23: =H10<3/1440 -> TRUE | I23: =I10<3/1440 -> TRUE | J23: =J10<3/1440 -> TRUE | ... Q23: =Q10<3/1440 -> TRUE
A24: 31200 | B24: Zutphen | C24: =C10<3/1440 -> FALSE | D24: =D10<3/1440 -> FALSE | E24: =E10<3/1440 -> FALSE | F24: =F10<3/1440 -> FALSE | G24: =G10<3/1440 -> TRUE | H24: =H10<3/1440 -> TRUE | I24: =I10<3/1440 -> TRUE | J24: =J10<3/1440 -> TRUE | ... Q24: =Q10<3/1440 -> TRUE
A25: 7900 | B25: Zwolle | C25: =C12<3/1440 -> TRUE | D25: =D12<3/1440 -> TRUE | E25: =E12<3/1440 -> TRUE | F25: =F12<3/1440 -> TRUE | G25: =G12<3/1440 -> TRUE | H25: =H12<3/1440 -> TRUE | I25: =I12<3/1440 -> TRUE | J25: =J12<3/1440 -> TRUE | ... Q25: =Q12<3/1440 -> TRUE
A26: Punctuality | C26: =COUNTIF(C16:C21,TRUE) / 6 -> 1 | D26: =COUNTIF(D16:D21,TRUE) / 6 -> 1 | E26: =COUNTIF(E16:E21,TRUE) / 6 -> 0.83333333 | F26: =COUNTIF(F16:F21,TRUE) / 6 -> 0.83333333 | G26: =COUNTIF(G16:G21,TRUE) / 6 -> 0.83333333 | H26: =COUNTIF(H16:H21,TRUE) / 6 -> 0.83333333 | I26: =COUNTIF(I16:I21,TRUE) / 6 -> 0.83333333 | J26: =COUNTIF(J16:J21,TRUE) / 6 -> 0.83333333 | ... Q26: =COUNTIF(Q16:Q21,TRUE) / 6 -> 1
A28: Diff ICE delay BB and Amf | C28: N/A | D28: N/A | E28: N/A | F28: N/A | G28: N/A | H28: N/A | I28: N/A | J28: N/A | K28: N/A | L28: N/A | M28: N/A | N28: N/A | O28: N/A | P28: N/A | Q28: N/A | R28: Extra delay
A29: Diff ICE delay BB and Amf | C29: =C1-C2 -> #VALUE! | D29: =D1-D2 -> #VALUE! | E29: =E1-E2 -> #VALUE! | F29: =F1-F2 -> #VALUE! | G29: =G1-G2 -> #VALUE! | H29: =H1-H2 -> #VALUE! | I29: =I1-I2 -> #VALUE! | J29: =J1-J2 -> #VALUE! | ... Q29: =Q1-Q2 -> #VALUE! | R29: Less delay
A31: Regional transfer | C31: =(C20+C21+C23+C24+C25)/5 -> 0.6 | D31: =(D20+D21+D23+D24+D25)/5 -> 0.6 | E31: =(E20+E21+E23+E24+E25)/5 -> 0.6 | F31: =(F20+F21+F23+F24+F25)/5 -> 0.6 | G31: =(G20+G21+G23+G24+G25)/5 -> 1 | H31: =(H20+H21+H23+H24+H25)/5 -> 1 | I31: =(I20+I21+I23+I24+I25)/5 -> 1 | J31: =(J20+J21+J23+J24+J25)/5 -> 1 | ... Q31: =(Q20+Q21+Q23+Q24+Q25)/5 -> 1

Sheet Overtake Rijssen
A1: ICE Delay Odzg | C1: 0.0020833333 | D1: 0.0027777778 | E1: 0.0034722222 | F1: 0.0041666667 | G1: 0.0048611111 | H1: 0.0055555556 | I1: 0.00625 | J1: 0.0069444444 | K1: 0.0076388889 | L1: 0.0083333333 | M1: 0.0090277778 | N1: 0.0097222222 | O1: 0.010416667 | P1: 0.013888889 | Q1: 0.017361111 | R1: Originele vertrektijd Odzg = 09:56:06
A2: 140/240 | B2: Amersfoort | C2: 0 | D2: 0 | E2: 0 | F2: 0.00016203704 | G2: 0.0078240741 | H2: 0.0078240741 | I2: 0.0078240741 | J2: 0.0078240741 | K2: 0.0078240741 | L2: 0.0078240741 | M2: 0.0078240741 | N2: 0.0078240741 | O2: 0.0078240741 | P2: 0.017476852 | Q2: 0.018240741 | R2: A140-late | T2: Originele aankomst Amf = 10:24:00
A3: 1700 | B3: Utrecht | C3: 0.011365741 | D3: 0.011365741 | E3: 0.011365741 | F3: 0.011365741 | G3: 0.011365741 | H3: 0.011365741 | I3: 0.011365741 | J3: 0.011365741 | K3: 0.011365741 | L3: 0.011365741 | M3: 0.011365741 | N3: 0.011365741 | O3: 0.011365741 | P3: 0 | Q3: 0 | R3: C1700-17
A4: 7000 | B4: Apeldoorn | C4: 0.0034027778 | D4: 0.0034027778 | E4: 0.0034259259 | F4: 0.0037962963 | G4: 0.005625 | H4: 0.005625 | I4: 0.005625 | J4: 0.005625 | K4: 0.005625 | L4: 0.005625 | M4: 0.0056018519 | N4: 0.005462963 | O4: 0.0059259259 | P4: 0.014837963 | Q4: 0.022592593 | R4: A7000-15
A5: 31200 | B5: Goor | C5: 0.0006712963 | D5: 0.00125 | E5: 0.0028703704 | F5: 0.0028703704 | G5: 0 | H5: 0 | I5: 0 | J5: 0 | K5: 0 | L5: 0 | M5: 0 | N5: 0 | O5: 0 | P5: 0 | Q5: 0 | R5: D31200-18
A6: 7900 | B6: Nijverdal | C6: 0 | D6: 0.00037037037 | E6: 0.0010648148 | F6: 0.0017592593 | G6: 0.0016203704 | H6: 0.0016203704 | I6: 0.0016203704 | J6: 0.0016203704 | K6: 0.0016203704 | L6: 0.0015277778 | M6: 0.0021064815 | N6: 0.0028009259 | O6: 0.0034953704 | P6: 0 | Q6: 0 | R6: A7900-17
A7: 31300 | B7: Amersfoort | C7: 0 | D7: 0 | E7: 0 | F7: 0 | G7: 0 | H7: 0 | I7: 0 | J7: 0 | K7: 0 | L7: 0 | M7: 0 | N7: 0 | O7: 0 | P7: 0 | Q7: 0 | R7: A31300-19
A8: 3600 | B8: Zwolle | C8: 0.0042592593 | D8: 0.0042592593 | E8: 0.0046759259 | F8: 0.0053703704 | G8: 0.00094907407 | H8: 0.00094907407 | I8: 0.00094907407 | J8: 0.00094907407 | K8: 0.00094907407 | L8: 0.00094907407 | M8: 0.00094907407 | N8: 0.00094907407 | O8: 0.00094907407 | P8: 0.00094907407 | Q8: 0.00094907407
A9: 20350 | B9: Hengelo | C9: 0 | D9: 0 | E9: 0 | F9: 0 | G9: 0 | H9: 0 | I9: 0 | J9: 0 | K9: 0 | L9: 0 | M9: 0 | N9: 0 | O9: 0.00069444444 | P9: 0.00069444444 | Q9: 0 | R9: B36100-18
A10: 31200 | B10: Hengelo | C10: 0.0023148148 | D10: 0.0028935185 | E10: 0.003587963 | F10: 0.0042824074 | G10: 0.00011574074 | H10: 0.00011574074 | I10: 0.00011574074 | J10: 0.00011574074 | K10: 0.00011574074 | L10: 0.00011574074 | M10: 0.00011574074 | N10: 0.00011574074 | O10: 0.00011574074 | P10: 0.00011574074 | Q10: 0.00011574074
A11: 31200 | B11: Zutphen | C11: 0.00016203704 | D11: 0.00027777778 | E11: 0.001875 | F11: 0.001875 | G11: 0.00016203704 | H11: 0.00016203704 | I11: 0.00016203704 | J11: 0.00016203704 | K11: 0.00016203704 | L11: 0.00016203704 | M11: 0.00016203704 | N11: 0.00016203704 | O11: 0.00016203704 | P11: 0.00016203704 | Q11: 0.00016203704
A12: 7900 | B12: Zwolle | C12: 0 | D12: 0 | E12: 0 | F12: 0 | G12: 0 | H12: 0 | I12: 0 | J12: 0 | K12: 0 | L12: 0 | M12: 0 | N12: 0 | O12: 0 | P12: 0 | Q12: 0
A13: Total delay all trains in the scope at the first hub outside the corridor | C13: =SUM(C3:C8) -> 0.019699074 | D13: =SUM(D3:D8) -> 0.020648148 | E13: =SUM(E3:E8) -> 0.023402778 | F13: =SUM(F3:F8) -> 0.025162037 | G13: =SUM(G3:G8) -> 0.019560185 | H13: =SUM(H3:H8) -> 0.019560185 | I13: =SUM(I3:I8) -> 0.019560185 | J13: =SUM(J3:J8) -> 0.019560185 | ... Q13: =SUM(Q3:Q8) -> 0.023541667
A15: 140/240 | B15: Amersfoort | C15: =C2<6/1440 -> TRUE | D15: =D2<6/1440 -> TRUE | E15: =E2<6/1440 -> TRUE | F15: =F2<6/1440 -> TRUE | G15: =G2<6/1440 -> FALSE | H15: =H2<6/1440 -> FALSE | I15: =I2<6/1440 -> FALSE | J15: =J2<6/1440 -> FALSE | ... Q15: =Q2<6/1440 -> FALSE
A16: 1700 | B16: Utrecht | C16: =C3<3/1440 -> FALSE | D16: =D3<3/1440 -> FALSE | E16: =E3<3/1440 -> FALSE | F16: =F3<3/1440 -> FALSE | G16: =G3<3/1440 -> FALSE | H16: =H3<3/1440 -> FALSE | I16: =I3<3/1440 -> FALSE | J16: =J3<3/1440 -> FALSE | ... Q16: =Q3<3/1440 -> TRUE
A17: 7000 | B17: Apeldoorn | C17: =C4<3/1440 -> FALSE | D17: =D4<3/1440 -> FALSE | E17: =E4<3/1440 -> FALSE | F17: =F4<3/1440 -> FALSE | G17: =G4<3/1440 -> FALSE | H17: =H4<3/1440 -> FALSE | I17: =I4<3/1440 -> FALSE | J17: =J4<3/1440 -> FALSE | ... Q17: =Q4<3/1440 -> FALSE
A18: 31200 | B18: Goor | C18: =C5<3/1440 -> TRUE | D18: =D5<3/1440 -> TRUE | E18: =E5<3/1440 -> FALSE | F18: =F5<3/1440 -> FALSE | G18: =G5<3/1440 -> TRUE | H18: =H5<3/1440 -> TRUE | I18: =I5<3/1440 -> TRUE | J18: =J5<3/1440 -> TRUE | ... Q18: =Q5<3/1440 -> TRUE
A19: 7900 | B19: Nijverdal | C19: =C6<3/1440 -> TRUE | D19: =D6<3/1440 -> TRUE | E19: =E6<3/1440 -> TRUE | F19: =F6<3/1440 -> TRUE | G19: =G6<3/1440 -> TRUE | H19: =H6<3/1440 -> TRUE | I19: =I6<3/1440 -> TRUE | J19: =J6<3/1440 -> TRUE | ... Q19: =Q6<3/1440 -> TRUE
A20: 31300 | B20: Amersfoort | C20: =C7<3/1440 -> TRUE | D20: =D7<3/1440 -> TRUE | E20: =E7<3/1440 -> TRUE | F20: =F7<3/1440 -> TRUE | G20: =G7<3/1440 -> TRUE | H20: =H7<3/1440 -> TRUE | I20: =I7<3/1440 -> TRUE | J20: =J7<3/1440 -> TRUE | ... Q20: =Q7<3/1440 -> TRUE
A21: 3600 | B21: Zwolle | C21: =C8<3/1440 -> FALSE | D21: =D8<3/1440 -> FALSE | E21: =E8<3/1440 -> FALSE | F21: =F8<3/1440 -> FALSE | G21: =G8<3/1440 -> TRUE | H21: =H8<3/1440 -> TRUE | I21: =I8<3/1440 -> TRUE | J21: =J8<3/1440 -> TRUE | ... Q21: =Q8<3/1440 -> TRUE
A22: 20350 | B22: Hengelo | C22: =C9<3/1440 -> TRUE | D22: =D9<3/1440 -> TRUE | E22: =E9<3/1440 -> TRUE | F22: =F9<3/1440 -> TRUE | G22: =G9<3/1440 -> TRUE | H22: =H9<3/1440 -> TRUE | I22: =I9<3/1440 -> TRUE | J22: =J9<3/1440 -> TRUE | ... Q22: =Q9<3/1440 -> TRUE
A23: 31200 | B23: Hengelo | C23: =C10<3/1440 -> FALSE | D23: =D10<3/1440 -> FALSE | E23: =E10<3/1440 -> FALSE | F23: =F10<3/1440 -> FALSE | G23: =G10<3/1440 -> TRUE | H23: =H10<3/1440 -> TRUE | I23: =I10<3/1440 -> TRUE | J23: =J10<3/1440 -> TRUE | ... Q23: =Q10<3/1440 -> TRUE
A24: 31200 | B24: Zutphen | C24: =C10<3/1440 -> FALSE | D24: =D10<3/1440 -> FALSE | E24: =E10<3/1440 -> FALSE | F24: =F10<3/1440 -> FALSE | G24: =G10<3/1440 -> TRUE | H24: =H10<3/1440 -> TRUE | I24: =I10<3/1440 -> TRUE | J24: =J10<3/1440 -> TRUE | ... Q24: =Q10<3/1440 -> TRUE
A25: 7900 | B25: Zwolle | C25: =C12<3/1440 -> TRUE | D25: =D12<3/1440 -> TRUE | E25: =E12<3/1440 -> TRUE | F25: =F12<3/1440 -> TRUE | G25: =G12<3/1440 -> TRUE | H25: =H12<3/1440 -> TRUE | I25: =I12<3/1440 -> TRUE | J25: =J12<3/1440 -> TRUE | ... Q25: =Q12<3/1440 -> TRUE
A26: Punctuality | C26: =COUNTIF(C16:C21,TRUE) / 6 -> 0.5 | D26: =COUNTIF(D16:D21,TRUE) / 6 -> 0.5 | E26: =COUNTIF(E16:E21,TRUE) / 6 -> 0.33333333 | F26: =COUNTIF(F16:F21,TRUE) / 6 -> 0.33333333 | G26: =COUNTIF(G16:G21,TRUE) / 6 -> 0.66666667 | H26: =COUNTIF(H16:H21,TRUE) / 6 -> 0.66666667 | I26: =COUNTIF(I16:I21,TRUE) / 6 -> 0.66666667 | J26: =COUNTIF(J16:J21,TRUE) / 6 -> 0.66666667 | ... Q26: =COUNTIF(Q16:Q21,TRUE) / 6 -> 0.83333333
A28: Diff ICE delay BB and Amf | C28: =C2-C1 -> -0.0020833333 | D28: =D2-D1 -> -0.0027777778 | E28: =E2-E1 -> -0.0034722222 | F28: =F2-F1 -> -0.0040046296 | G28: =G2-G1 -> 0.002962963 | H28: =H2-H1 -> 0.0022685185 | I28: =I2-I1 -> 0.0015740741 | J28: =J2-J1 -> 0.00087962963 | ... Q28: =Q2-Q1 -> 0.00087962963 | R28: Extra delay
A29: Diff ICE delay BB and Amf | C29: =C1-C2 -> 0.0020833333 | D29: =D1-D2 -> 0.0027777778 | E29: =E1-E2 -> 0.0034722222 | F29: =F1-F2 -> 0.0040046296 | G29: =G1-G2 -> -0.002962963 | H29: =H1-H2 -> -0.0022685185 | I29: =I1-I2 -> -0.0015740741 | J29: =J1-J2 -> -0.00087962963 | ... Q29: =Q1-Q2 -> -0.00087962963 | R29: Less delay
A31: Regional transfer | C31: =(C20+C21+C23+C24+C25)/5 -> 0.4 | D31: =(D20+D21+D23+D24+D25)/5 -> 0.4 | E31: =(E20+E21+E23+E24+E25)/5 -> 0.4 | F31: =(F20+F21+F23+F24+F25)/5 -> 0.4 | G31: =(G20+G21+G23+G24+G25)/5 -> 1 | H31: =(H20+H21+H23+H24+H25)/5 -> 1 | I31: =(I20+I21+I23+I24+I25)/5 -> 1 | J31: =(J20+J21+J23+J24+J25)/5 -> 1 | ... Q31: =(Q20+Q21+Q23+Q24+Q25)/5 -> 1

Sheet Alternative ICE Paths
A1: ICE Delay Odzg | C1: 0.0020833333 | D1: 0.0027777778 | E1: 0.0034722222 | F1: 0.0041666667 | G1: 0.0048611111 | H1: 0.0055555556 | I1: 0.00625 | J1: 0.0069444444 | K1: 0.0076388889 | L1: 0.0083333333 | M1: 0.0090277778 | N1: 0.0097222222 | O1: 0.010416667 | P1: 0.013888889 | Q1: 0.017361111 | R1: Originele vertrektijd Odzg = 09:56:06
A2: 140/240 | B2: Amersfoort | C2: 0.017592593 | D2: 0.017592593 | E2: 0.017592593 | F2: 0.017592593 | G2: 0.017592593 | H2: 0.017592593 | I2: 0.017592593 | J2: 0.017592593 | K2: 0.017592593 | L2: 0.017592593 | M2: 0.017592593 | N2: 0.017592593 | O2: 0.017592593 | P2: 0.017592593 | Q2: 0.017592593 | R2: A140-late | T2: Originele aankomst Amf = 10:24:00
A3: 1700 | B3: Utrecht | C3: 0.0015509259 | D3: 0.0015509259 | E3: 0.0015509259 | F3: 0.0015509259 | G3: 0.0015509259 | H3: 0.0015509259 | I3: 0.0015509259 | J3: 0.0015509259 | K3: 0.0015509259 | L3: 0.0015509259 | M3: 0.0015509259 | N3: 0.0015509259 | O3: 0.0015509259 | P3: 0.0015509259 | Q3: 0.0015509259 | R3: C1700-17
A4: 7000 | B4: Apeldoorn | C4: 0.0013657407 | D4: 0.0013657407 | E4: 0.0013657407 | F4: 0.0013657407 | G4: 0.0013657407 | H4: 0.0013657407 | I4: 0.0013657407 | J4: 0.0013657407 | K4: 0.0013657407 | L4: 0.0013657407 | M4: 0.0013657407 | N4: 0.0013657407 | O4: 0.0013657407 | P4: 0.0013657407 | Q4: 0.0013657407 | R4: A7000-15
A5: 31200 | B5: Goor | C5: 0 | D5: 0 | E5: 0 | F5: 0 | G5: 0 | H5: 0 | I5: 0 | J5: 0 | K5: 0 | L5: 0 | M5: 0 | N5: 0 | O5: 0 | P5: 0 | Q5: 0 | R5: D31200-18
A6: 7900 | B6: Nijverdal | C6: 0 | D6: 0 | E6: 0 | F6: 0 | G6: 0 | H6: 0 | I6: 0 | J6: 0 | K6: 0 | L6: 0 | M6: 0 | N6: 0 | O6: 0 | P6: 0 | Q6: 0 | R6: A7900-17
A7: 31300 | B7: Amersfoort | C7: 0 | D7: 0 | E7: 0 | F7: 0 | G7: 0 | H7: 0 | I7: 0 | J7: 0 | K7: 0 | L7: 0 | M7: 0 | N7: 0 | O7: 0 | P7: 0 | Q7: 0 | R7: A31300-19
A8: 3600 | B8: Zwolle | C8: 0.00094907407 | D8: 0.00094907407 | E8: 0.00094907407 | F8: 0.00094907407 | G8: 0.00094907407 | H8: 0.00094907407 | I8: 0.00094907407 | J8: 0.00094907407 | K8: 0.00094907407 | L8: 0.00094907407 | M8: 0.00094907407 | N8: 0.00094907407 | O8: 0.00094907407 | P8: 0.00094907407 | Q8: 0.00094907407 | R8: A3600-5
A9: 20350 | B9: Hengelo | C9: 0 | D9: 0 | E9: 0 | F9: 0 | G9: 0 | H9: 0 | I9: 0 | J9: 0 | K9: 0 | L9: 0 | M9: 0 | N9: 0.00016203704 | O9: 0.00085648148 | P9: 0 | Q9: 0 | R9: B36100-18
A10: 31200 | B10: Hengelo | C10: 0.00011574074 | D10: 0.00011574074 | E10: 0.00011574074 | F10: 0.00011574074 | G10: 0.00011574074 | H10: 0.00011574074 | I10: 0.00011574074 | J10: 0.00011574074 | K10: 0.00011574074 | L10: 0.00011574074 | M10: 0.00011574074 | N10: 0.00011574074 | O10: 0.00011574074 | P10: 0.00011574074 | Q10: 0.00011574074
